Workbook

Sheet Kriteriji
A1: Ručna provjera preciznosti upita D AND E (OpenAlex) — kriteriji kodiranja
A3: Svaki zapis dobiva jednu od tri oznake:
A4: A — RELEVANTAN: bespilotna letjelica (UAV/UAS/dron) je senzorska platforma ILI predmet rada, A primjena je ekološka / okolišna: divlje životinje, staništa, šume i vegetacija u prirodnom okolišu, vode, zrak i emisije plinova, požari, obala i geomorfologija okoliša, onečišćenje, zaštićena područja, bioraznolikost.
A5: B — GRANIČAN: UAV jest platforma, ali primjena je susjedna: precizna poljoprivreda (usjevi, prinos, korovi, fenotipizacija), urbanistička/geodetska izmjera, hazardi bez ekološkog fokusa, generička UAV tehnologija koja okoliš samo spominje.
A6: C — NERELEVANTAN: nema zračne bespilotne letjelice („drone“ = trut, „UAS“ = drugi akronim, podvodni dronovi, književnost) ILI UAV bez ikakve okolišne primjene (vojna, dostava, sigurnost, softver).
A8: Postupak: (1) pročitajte naslov i sažetak; (2) ako sažetak nedostaje, otvorite poveznicu (OpenAlex ID) i pročitajte rad; (3) u stupac „KONAČNA OCJENA“ upišite A, B ili C — stupac je unaprijed popunjen prijedlogom (AI), koji je samo pomoć i može se promijeniti; (4) po potrebi napišite napomenu. List „Sažetak“ se sam preračunava.
A10: Uzorci: (a) 100 slučajnih zapisa iz cijelog razdoblja 2005.–2025. (OpenAlex sample=100, seed=20260826); (b) 50 slučajnih zapisa iz ranog razdoblja 2005.–2015. (seed=20260827) za provjeru stabilnosti preciznosti kroz vrijeme. Dohvat 27. 8. 2026.
A12: Za rad se izvještava: preciznost u strogom smislu P(A) i u širem smislu P(A ili B), s Wilsonovim 95 % intervalom; test razlike ranog i cijelog uzorka; te osjetljivost trenda na strogi upit (D AND E NOT poljoprivredni pojmovi), list „Strogi_upit“.
A14: Preporuka za drugu osobu (inter-rater): neka koautor neovisno kodira barem 30 zapisa u praznoj kopiji stupca; slaganje se izvještava kao postotak ili Cohenova kappa.

Sheet Sažetak
A1: Sažetak provjere preciznosti (sve formule; mijenja se automatski kad promijenite KONAČNU OCJENU)
A3: Uzorak A (2005.–2025., n = 100)
A4: n (ocijenjeno) | B4: =COUNTIF(Uzorak_100!$L$5:$L$104,"A")+COUNTIF(Uzorak_100!$L$5:$L$104,"B")+COUNTIF(Uzorak_100!$L$5:$L$104,"C") -> 100
A5: A — relevantan | B5: =COUNTIF(Uzorak_100!$L$5:$L$104,"A") -> 42
A6: B — graničan | B6: =COUNTIF(Uzorak_100!$L$5:$L$104,"B") -> 38
A7: C — nerelevantan | B7: =COUNTIF(Uzorak_100!$L$5:$L$104,"C") -> 20
A8: P(A) stroga preciznost | B8: =IF(B4>0,B5/B4,"") -> 0.42
A9: P(A ili B) šira preciznost | B9: =IF(B4>0,(B5+B6)/B4,"") -> 0.8
A10: Wilson 95 % donja, P(A) | B10: =IF(B4>0,((B8+1.96^2/(2*B4))-1.96*SQRT(B8*(1-B8)/B4+1.96^2/(4*B4^2)))/(1+1.96^2/B4),"") -> 0.32798225
A11: Wilson 95 % gornja, P(A) | B11: =IF(B4>0,((B8+1.96^2/(2*B4))+1.96*SQRT(B8*(1-B8)/B4+1.96^2/(4*B4^2)))/(1+1.96^2/B4),"") -> 0.51793692
A12: Wilson 95 % donja, P(A∪B) | B12: =IF(B4>0,((B9+1.96^2/(2*B4))-1.96*SQRT(B9*(1-B9)/B4+1.96^2/(4*B4^2)))/(1+1.96^2/B4),"") -> 0.71116904
A13: Wilson 95 % gornja, P(A∪B) | B13: =IF(B4>0,((B9+1.96^2/(2*B4))+1.96*SQRT(B9*(1-B9)/B4+1.96^2/(4*B4^2)))/(1+1.96^2/B4),"") -> 0.86663408
A15: Uzorak B (2005.–2015., n = 50)
A16: n (ocijenjeno) | B16: =COUNTIF(Uzorak_50_rano!$L$5:$L$54,"A")+COUNTIF(Uzorak_50_rano!$L$5:$L$54,"B")+COUNTIF(Uzorak_50_rano!$L$5:$L$54,"C") -> 50
A17: A — relevantan | B17: =COUNTIF(Uzorak_50_rano!$L$5:$L$54,"A") -> 27
A18: B — graničan | B18: =COUNTIF(Uzorak_50_rano!$L$5:$L$54,"B") -> 8
A19: C — nerelevantan | B19: =COUNTIF(Uzorak_50_rano!$L$5:$L$54,"C") -> 15
A20: P(A) stroga preciznost | B20: =IF(B16>0,B17/B16,"") -> 0.54
A21: P(A ili B) šira preciznost | B21: =IF(B16>0,(B17+B18)/B16,"") -> 0.7
A22: Wilson 95 % donja, P(A) | B22: =IF(B16>0,((B20+1.96^2/(2*B16))-1.96*SQRT(B20*(1-B20)/B16+1.96^2/(4*B16^2)))/(1+1.96^2/B16),"") -> 0.40398634
A23: Wilson 95 % gornja, P(A) | B23: =IF(B16>0,((B20+1.96^2/(2*B16))+1.96*SQRT(B20*(1-B20)/B16+1.96^2/(4*B16^2)))/(1+1.96^2/B16),"") -> 0.67030565
A24: Wilson 95 % donja, P(A∪B) | B24: =IF(B16>0,((B21+1.96^2/(2*B16))-1.96*SQRT(B21*(1-B21)/B16+1.96^2/(4*B16^2)))/(1+1.96^2/B16),"") -> 0.56249388
A25: Wilson 95 % gornja, P(A∪B) | B25: =IF(B16>0,((B21+1.96^2/(2*B16))+1.96*SQRT(B21*(1-B21)/B16+1.96^2/(4*B16^2)))/(1+1.96^2/B16),"") -> 0.80896611
A27: Razlika P(A): uzorak B (rano) − uzorak A (cijelo razdoblje)
A28: razlika udjela | B28: =B20-B8 -> 0.12
A29: z (dvoproporcijski test, združeni p) | B29: =IF(AND(B4>0,B16>0),(B20-B8)/SQRT(((B5+B17)/(B4+B16))*(1-(B5+B17)/(B4+B16))*(1/B4+1/B16)),"") -> 1.3900961
A30: p (dvostrano) | B30: =IF(B29="","",2*(1-NORMSDIST(ABS(B29)))) -> 0.1644997
A31: Tumačenje: p > 0,05 → nema dokaza da se preciznost mijenjala kroz vrijeme; trendovi i udjeli tada nisu pristrani zbog šuma upita.
A33: Napomena: formule se odnose na stupac L (KONAČNA OCJENA) oba lista; prazne ćelije se ne broje.

Sheet Uzorak_100
A1: Uzorak A: 100 slučajnih zapisa, 2005.–2025. (seed 20260826)
A2: Žuti stupac = KONAČNA OCJENA (A/B/C), popunite ili potvrdite; prijedlog (AI) je samo pomoć.
A4: # | B4: Godina | C4: Naslov | D4: Časopis / izvor | E4: OpenAlex tema | F4: OpenAlex ID (poveznica) | G4: DOI | H4: UAV pojam | I4: Sažetak (skraćen) | J4: Prijedlog (AI) | K4: Obrazloženje prijedloga | L4: KONAČNA OCJENA | M4: Napomena ocjenjivača
A5: 1 | B5: 2023 | C5: Virtual nature makes knowledge beautiful | D5: Frontiers in Virtual Reality | E5: Virtual Reality Applications and Impacts | F5: https://openalex.org/W4324088175 | G5: https://doi.org/10.3389/frvir.2023.1100540 | H5: drone | I5: This is a perspective that presents a viewpoint on immersive informal learning applications built as digital twins of the natural world. Such applications provide multimodal, interactive, immersive, embodied, and sensory experiences unique and different from typical game art environments because they are geospatial visualizations of data and information derived from ecological field plot studies, geographical information systems, drone images, and botanically correct 3D plant models visualized in real-time interactive game engines. Since they are constructed from geometric objects, they can programmatically self-express semantic data and connect to knowledge stores on the Internet to create … | J5: C | K5: Virtualna stvarnost; dronske snimke samo kao izvor podataka | L5: C
A6: 2 | B6: 2025 | C6: Eddy-covariance fluxes of CO 2 , CH 4 and N 2 O in a drained peatland forest after clear-cutting | D6: Biogeosciences | E6: Peatlands and Wetlands Ecology | F6: https://openalex.org/W4408194576 | G6: https://doi.org/10.5194/bg-22-1277-2025 | H6: uav | I6: Abstract. Rotation forestry based on clear-cut harvesting, site preparation, planting and intermediate thinnings is currently the dominant management approach in Fennoscandia. However, understanding of the greenhouse gas (GHG) emissions following clear-cutting remains limited, particularly in drained peatland forests. In this study, we report eddy-covariance-based (EC-based) net emissions of carbon dioxide (CO2), methane (CH4) and nitrous oxide (N2O) from a fertile drained boreal peatland forest 1 year after wood harvest. Our results show that, at an annual scale, the site was a net CO2 source. The CO2 emissions dominate the total annual GHG balance (23.3 t CO2 eq. ha−1 yr−1, 22.4–24.1 t CO2… | J6: A | K6: UAV spektralno snimanje tla u studiji GHG emisija tresetišta | L6: A
A7: 3 | B7: 2025 | C7: River-to-sea plastic pollution: A pilot toolbox for the Caspian Sea | D7: Chemosphere | E7: Microplastics and Plastic Pollution | F7: https://openalex.org/W4414038221 | G7: https://doi.org/10.1016/j.chemosphere.2025.144667 | H7: uav | I7: This study presents the first integrated assessment of plastic pollution at the Kura River delta, where the river enters the hydrologically enclosed Caspian Sea. We applied a modular toolbox comprising four complementary components: high-resolution hydrodynamic modeling to predict debris convergence zones, UAV-based mapping to survey shoreline conditions, automated object-based image analysis for debris detection and classification, and standardized field monitoring by trained community participants for ground-truthing and source identification. Using this framework, we identified debris accumulation hotspots and developed a replicable approach for assessing plastic pollution in semi-enclose… | J7: A | K7: UAV kartiranje plastičnog onečišćenja obale | L7: A
A8: 4 | B8: 2018 | C8: Inventory of the quantitative characteristics of single oak trees with nonparametric methods of Support Vector Machines and Decision Tree on satellite images of WorldView-2 and UAV | D8: DOAJ (DOAJ: Directory of Open Access Journals) | E8: Remote Sensing and LiDAR Applications | F8: https://openalex.org/W2892110396 | G8: https://doi.org/10.22120/jwb.2018.84168.1022 | H8: uav | I8: To achieve effective forests management it is necessary to obtain reliable statistical data like the number of stands, diameter at breast height (DBH), and ‎crown volume. While traditional methods of the forests measurements are very labor intensive and time consuming, remote sensing can provide up-to-date and low cost ‎data. In comparing ot other sensors, the satellite WV-2 ‎generate very high resolution images that can be used in the forest management practices. In the present study, we aimed to estimate parameters related on the single trees characteristics using decision tree ‎method and Support Vector Machines classification with complex matrix evaluation and Area ‎under operating chara… | J8: A | K8: Inventura hrasta, UAV + satelit, upravljanje šumama | L8: A
A9: 5 | B9: 2025 | C9: A novel waveform-based pixel decomposition method for farmland shelterbelts width extraction using Sentinel−2 multi-spectral and UAV RGB images | D9: International Journal of Digital Earth | E9: Soil erosion and sediment transport | F9: https://openalex.org/W4417196979 | G9: https://doi.org/10.1080/17538947.2025.2584509 | H9: uav | I9: As vital components of the Three-North Shelter Forest Program, farmland shelterbelts play a critical role in enhancing agricultural resilience. Among their structural attributes, shelterbelt width stands out as a key parameter that directly influences their ecological effectiveness. This study proposed a novel waveform-based pixel decomposition method (WBPD) for extracting the shelterbelt width. By integrating Sentinel−2 images with UAV-derived orthophoto maps, we extracted fractional coverage (FC) waveforms and enhanced width estimation through refined pixel decomposition. The main findings are as follows: (1) The dimidiate pixel model accurately estimated FC (R² = 0.764, RMSE = 0.15), with… | J9: A | K9: Širina šumskih pojaseva, UAV RGB (ekološka funkcija) | L9: A
A10: 6 | B10: 2022 | C10: Correlation of UAV and satellite-derived vegetation indices with cotton physiological parameters and their use as a tool for scheduling variable rate irrigation in cotton | D10: Precision Agriculture | E10: Remote Sensing in Agriculture | F10: https://openalex.org/W4293531406 | G10: https://doi.org/10.1007/s11119-022-09948-6 | H10: uav, unmanned aerial | I10: Abstract Current irrigation management zones (IMZs) for variable rate irrigation (VRI) systems are static. They are delineated in the beginning of the season and used thereafter. However, recent research has shown that IMZ boundaries are transient and change with time during the growing season. The primary goal of this study was to explore the potential of using vegetation indices (VIs) developed from unmanned aerial vehicle (UAV) and satellite images to predict cotton physiological parameters that can be used to delineate in-season boundaries of IMZs. A 2 year study was conducted in a 38 ha commercial cotton field in southwestern Georgia, USA. Throughout the two growing seasons, VIs were ca… | J10: B | K10: Precizna poljoprivreda: pamuk, navodnjavanje | L10: B
A11: 7 | B11: 2019 | C11: Morphometric characterization of the stingless bees, Tetragonula iridipennis Smith (Hymenoptera: Apidae) | D11: Journal of Entomology and Zoology Studies | E11: Plant and animal studies | F11: https://openalex.org/W3088000011 | H11: drone, drones | I11: Although, a good diversity of Tetragonula iridipennis is occurred in Northern Parts of the country, still very less studies have been conduced to explore their habitat and morphological features. Again, morphometry of drones of T. iridipennis is first time recorded in Temperate region/ Northern Parts of India. As by appearance, drone and worker bees look quite similar in appearance, the measurements of drone will help to distinguish them from worker bees. The studies will helpful in colonizing their feral colonies into hives and to design a suitable hives for their domestication.Significant differences were found in various body parts of all three castes. Further, results showed an important… | J11: C | K11: „Drone“ = trut (pčele) | L11: C
A12: 8 | B12: 2020 | C12: Evaluating the Use of Drones Equipped with Thermal Sensors as an Effective Method for Estimating Wildlife | D12: Wildlife Society Bulletin | E12: Wildlife Ecology and Conservation | F12: https://openalex.org/W3021841073 | G12: https://doi.org/10.1002/wsb.1090 | H12: drone, drones | I12: ABSTRACT Drones equipped with thermal sensors have shown ability to overcome some of the limitations often associated with traditional human‐occupied aerial surveys (e.g., low detection, high operational cost, human safety risk). However, their accuracy and reliability as a valid population technique have not been adequately tested. We tested the effectiveness of using a miniaturized thermal sensor equipped to a drone (thermal drone) for surveying white‐tailed deer ( Odocoileus virginianus ) populations using a captive deer population with a highly constrained (hereafter, known) abundance (151–163 deer, midpoint 157 [87–94 deer/km 2 , midpoint 90 deer/km 2 ]) at Auburn University's deer rese… | J12: A | K12: Termalni dronovi za popis divljači | L12: A
A13: 9 | B13: 2025 | C13: Advancing Water Hyacinth Recognition: Integration of Deep Learning and Multispectral Imaging for Precise Identification | D13: Remote Sensing | E13: Coastal wetland ecosystem dynamics | F13: https://openalex.org/W4407704902 | G13: https://doi.org/10.3390/rs17040689 | H13: drone | I13: The aquatic plant species Eichhornia crassipes, commonly known as water hyacinth, is indigenous to South America and is considered an invasive species. The invasive water hyacinth has caused significant economic and ecological damage by preventing sunlight from penetrating the surface of the water, resulting in the loss of aquatic life. To quantify the invasiveness and address the issue of accurately identifying plant species, water hyacinths have prompted numerous researchers to propose approaches to detect regions occupied by water hyacinths. One such solution involves the utilization of multispectral imaging which obtain detailed information about plant species based on the surface reflec… | J13: A | K13: Invazivna vodena biljka, dron + duboko učenje | L13: A
A14: 10 | B14: 2024 | C14: Semantic Segmentation in Large-Size Orthomosaics to Detect the Vegetation Area in Opuntia spp. Crop | D14: Journal of Imaging | E14: Botanical Research and Applications | F14: https://openalex.org/W4401206527 | G14: https://doi.org/10.3390/jimaging10080187 | H14: drones | I14: This study focuses on semantic segmentation in crop Opuntia spp. orthomosaics; this is a significant challenge due to the inherent variability in the captured images. Manual measurement of Opuntia spp. vegetation areas can be slow and inefficient, highlighting the need for more advanced and accurate methods. For this reason, we propose to use deep learning techniques to provide a more precise and efficient measurement of the vegetation area. Our research focuses on the unique difficulties posed by segmenting high-resolution images exceeding 2000 pixels, a common problem in generating orthomosaics for agricultural monitoring. The research was carried out on a Opuntia spp. cultivation located … | J14: B | K14: Poljoprivredna kultura Opuntia, segmentacija | L14: B
A15: 11 | B15: 2021 | C15: Evaluating eco-environment in urban agglomeration from a vegetation-impervious surface-soil-air framework: an example in Ningxia, China | D15: Journal of Applied Remote Sensing | E15: Urban Heat Island Mitigation | F15: https://openalex.org/W3138645229 | G15: https://doi.org/10.1117/1.jrs.15.014518 | H15: uas | I15: Urban agglomerations (UA) are the fastest growing regional types during recent years, especially in developing countries. Monitoring and evaluating the eco-environment quality of UA is significant for sustainability. The previous remote sensing models of urban eco-environment are generally based on the vegetation-impervious surface-soil framework, which neglects the air quality in urban areas. We constructed a vegetation-impervious surface-soil-air (VISA) framework and derived a remote sensing model of UA eco-environment (RSUAE) based on the VISA. The RSUAE can integrate the greenness, dryness and imperviousness, moisture, heat, and air turbidity. The new model was evaluated by comparing wit… | J15: C | K15: „UAS“ = urban agglomerations, nema letjelice | L15: C
A16: 12 | B16: 2024 | C16: Identification and Monitoring of Crop Pests and Diseases Based on Remote Sensing Technology | D16: Transactions on Environment Energy and Earth Sciences | E16: Remote Sensing and Land Use | F16: https://openalex.org/W4405388873 | G16: https://doi.org/10.62051/btdqj764 | H16: uav | I16: Identifying and monitoring crop pests and diseases are crucial to agricultural production, and they directly affect crop growth and the quality of agricultural products. This paper reviews crop pest and disease identification and monitoring techniques based on remote sensing imagery, emphasizing their advantages in providing timely and accurate information. The paper mainly summarizes the data sources for crop pest and disease detection, including satellite, UAV, aircraft, ground, and aerial remote sensing data, as well as laboratory monitoring data and seven types of multi-source data fusion. Four remote sensing monitoring techniques were discussed: spectral reflectance analysis, vegetation… | J16: B | K16: Pregled daljinskih istraživanja štetnika usjeva; UAV kao jedan izvor | L16: B
A17: 13 | B17: 2020 | C17: Contribution of Lightweight Revolving Laser Scanner, HiRes UAV LiDARs and Photogrammetry for Characterization of Coastal Aeolian Morphologies | D17: Journal of Coastal Research | E17: Aeolian processes and effects | F17: https://openalex.org/W3015499049 | G17: https://doi.org/10.2112/si95-213.1 | H17: uav | I17: Garcin, M.; Desmazes, F.; Nicolae Lerma, A.; Gouguet, L., and Météreau, V., 2020. Contribution of Lightweight Revolving Laser Scanner, HiRes UAV LiDARs and photogrammetry for characterization of coastal aeolian morphologies. In: Malvárez, G. and Navas, F. (eds.), Global Coastal Issues of 2020. Journal of Coastal Research, Special Issue No. 95, pp. 1094–1100. Coconut Creek (Florida), ISSN 0749-0208.The monitoring of coastal dunes changes in a context of climate change is a major issue for assessment of coastal hazards. While shoreline retreat and beach erosion are generally well characterized within coastal observatories, the monitoring of dunes changes under aeolian-driven processes are freq… | J17: A | K17: Obalne dine, UAV LiDAR i fotogrametrija | L17: A
A18: 14 | B18: 2025 | C18: UAV Photogrammetry-Based Leaf Area Index for Above-Ground Biomass Estimation in Wetlands | D18: IEEE Journal of Selected Topics in Applied Earth Observations and Remote Sensing | E18: Remote Sensing and LiDAR Applications | F18: https://openalex.org/W4409261290 | G18: https://doi.org/10.1109/jstars.2025.3558893 | H18: uav | I18: Wetlands are highly productive and biologically diverse environments that provide numerous ecosystem services. Effective monitoring methods are critical to ensure their preservation and management. This paper used UAV-derived RGB images and SfM photogrammetry to create point clouds. Primary tie points were utilized as they are the more suitable representation of the raw 3D information of the common features from the overlapping images. A Leaf Area Index (LAI) estimation workflow for LiDAR was then tested on the UAV-SfM point cloud of two wetland types – alpine peatland and coastal salt marsh- to assess its applicability. The LAI and AGB values for the peatland were 0.75 – 2.58 and 0 – 318.8 … | J18: A | K18: Biomasa močvara UAV fotogrametrijom | L18: A
A19: 15 | B19: 2021 | C19: An Improved Multi-Platform Stacked D-InSAR Method for Monitoring the Three-Dimensional Deformation of the Mining Area | D19: IEEE Access | E19: Synthetic Aperture Radar (SAR) Applications and Techniques | F19: https://openalex.org/W3158257030 | G19: https://doi.org/10.1109/access.2021.3076065 | H19: unmanned aerial | I19: The acquisition of information on fine surface three-dimensional deformation in a goaf is of great significance for the in-depth understanding of the law of mining subsidence and guiding the safe production and ecological restoration of the mining area. In this paper, three platform SAR satellite images are used for stacked D-InSAR processing to obtain the information on surface deformation in three line-of-sight directions. An improved three-dimensional decomposition model is proposed based on the difference between the COSMO-SkyMed and TerraSAR-X satellite heading angles, which are very small. The proposed method is verified by evaluating the three-dimensional deformation of the ground sur… | J19: B | K19: Deformacije rudarskog područja, UAV fotogrametrija kao pomoćni podatak | L19: B
A20: 16 | B20: 2023 | C20: Investigation of Combining Deep Learning Object Recognition with Drones for Forest Fire Detection and Monitoring | D20: International Journal of Advanced Computer Science and Applications | E20: Fire Detection and Safety Systems | F20: https://openalex.org/W4362571254 | G20: https://doi.org/10.14569/ijacsa.2023.0140342 | H20: drones, uavs, unmanned aerial | I20: Forest fires are a global environmental problem that can cause significant damage to natural resources and human lives. The increasing frequency and severity of forest fires have resulted in substantial losses of natural resources. To mitigate this, an effective fire detection and monitoring system is crucial. This work aims to explore and review the current advancement in the field of forest fire detection and monitoring using both drones or unmanned aerial vehicles (UAVs), and deep learning techniques. The utilization of drones fully equipped with specific sensors and cameras provides a cost-effective and efficient solution for real-time monitoring and early fire detection. In this paper, … | J20: A | K20: Detekcija šumskih požara dronovima | L20: A
A21: 17 | B21: 2024 | C21: Population Size and Spatial Distribution of the Mexican Blind Cavefish (Astyanax) within the Caves | D21: Fishes | E21: Subterranean biodiversity and taxonomy | F21: https://openalex.org/W4401894579 | G21: https://doi.org/10.3390/fishes9090334 | H21: drones | I21: The most studied cavefish in the world is Astyanax mexicanus, and the most frequently used specimens in research come from the Pachón cave in Northeast Mexico. A recent study using the capture–mark–recapture technique revealed that the Pachón population size is only in the hundreds of individuals, not in the thousands. This result raises serious concerns about their long-term survival and highlights the need to accurately estimate the population size of other Astyanax caves. In our study, we used a well-established, non-invasive method for estimating population size: the transect sampling method, which counts the abundance of organisms along a line at regular intervals. We used the 310 m lon… | J21: A | K21: Populacija špiljske ribe, dronovi u nepristupačnim galerijama | L21: A
A22: 18 | B22: 2021 | C22: Comparison of Outdoor Compost Pile Detection Using Unmanned Aerial Vehicle Images and Various Machine Learning Techniques | D22: Drones | E22: Remote Sensing and LiDAR Applications | F22: https://openalex.org/W3157060625 | G22: https://doi.org/10.3390/drones5020031 | H22: uav, unmanned aerial | I22: Since outdoor compost piles (OCPs) contain large amounts of nitrogen and phosphorus, they act as a major pollutant that deteriorates water quality, such as eutrophication and green algae, when the OCPs enter the river during rainfall. In South Korea, OCPs are frequently used, but there is a limitation that a lot of manpower and budget are consumed to investigate the current situation, so it is necessary to efficiently investigate the OCPs. This study compared the accuracy of various machine learning techniques for the efficient detection and management of outdoor compost piles (OCPs), a non-point pollution source in agricultural areas in South Korea, using unmanned aerial vehicle (UAV) image… | J22: A | K22: Detekcija kompostnih hrpi (zaštita voda) UAV-om | L22: A
A23: 19 | B23: 2024 | C23: Review of microclimate mapping methods in forestry | D23: Revista de la Facultad de Agronomía | E23: Remote Sensing and LiDAR Applications | F23: https://openalex.org/W4405805956 | G23: https://doi.org/10.47280/revfacagron(luz).v42.n1.iv | H23: drones, uav, uas, rpas | I23: The study of microclimates provides a several benefits that imply their importance to reduce the effects of climate change, so the mapping of microclimates emerges as an alternative for their identification and conservation. The objective of this review is to identify the techniques used in microclimate mapping. The methodology used was an exploratory review in databases such as Science Direct, Springer and IEEXplore, which determined that there is a shortage of works related to microclimate mapping, since only 19 works met the inclusion requirements of the review. It was determined that the main objective of the microclimate mapping focused on the tree canopy, the height and density of the … | J23: A | K23: Pregled kartiranja mikroklime u šumarstvu, uklj. dronove | L23: A
... A31: 27 | B31: 2023 | C31: Instance segmentation method for weed detection using UAV imagery in soybean fields | D31: Computers and Electronics in Agriculture | E31: Smart Agriculture and AI | F31: https://openalex.org/W4381435793 | G31: https://doi.org/10.1016/j.compag.2023.107994 | H31: uav | I31: (sažetak nije dostupan — otvoriti poveznicu) | J31: B | K31: Korovi u soji | L31: B
A32: 28 | B32: 2024 | C32: Drones and technopreneurship in Malaysia: unlocking the economic potential of drones in built environment development | D32: Universiti Putra Malaysia Institutional Repository (Universiti Putra Malaysia) | E32: UAV Applications and Optimization | F32: https://openalex.org/W7155285149 | H32: drone, drones, unmanned aerial | I32: Drones, with diverse technological capabilities, are poised to revolutionise various traditional tasks, particularly in-built environment development while driving economic growth, innovation, and job creation. Within the Malaysian context, drones have evolved beyond recreational use to become sophisticated unmanned aerial vehicles with untapped business potential. Against this backdrop, this paper explores a comprehensive review of drone development in Malaysia. Using a multidisciplinary approach, the review includes selected publication data from academic journals and online media published between 2018 and 2023, complemented with insights gathered from expert interviews. Aiming to bridge … | J32: C | K32: Poduzetništvo s dronovima | L32: C
A33: 29 | B33: 2025 | C33: Review of Technologies and Architectures for UAV-Air Quality Monitoring in Hazardous Environments | D33: Zenodo (CERN European Organization for Nuclear Research) | E33: UAV Applications and Optimization | F33: https://openalex.org/W7117579206 | G33: https://doi.org/10.5281/zenodo.18080722 | H33: uav, uavs, unmanned aerial | I33: Certain technologies enable remote monitoring in hazardous environments. These technologies range from wired and wireless communication, sensors, IoT, waste management, and cloud technologies. This paper reviews the technologies and architectures for Unmanned Aerial Vehicles' air quality monitoring systems in hazardous environments. It exposes the technologies and protocols associated with the UAV hardware, gas sensing, storage, and transmission. This paper identifies and discusses UAVs in air quality monitoring, IoT, wired and wireless communication technologies, choices, and applications in air quality monitoring in Hazardous environments. | J33: A | K33: Pregled UAV sustava za praćenje kakvoće zraka | L33: A
A34: 30 | B34: 2025 | C34: Strategic AI-Oriented Compliance Optimization Models for FinTechs Operating Across Multi-Jurisdictional Financial Ecosystems | D34: International Journal of Advanced Multidisciplinary Research and Studies | E34: FinTech, Crowdfunding, Digital Finance | F34: https://openalex.org/W4412640527 | G34: https://doi.org/10.62225/2583049x.2025.5.4.4592 | H34: (nije u naslovu/sažetku) | I34: The expansion of FinTech enterprises across international financial ecosystems has introduced complex compliance challenges stemming from heterogeneous regulatory environments. This review investigates the strategic deployment of Artificial Intelligence (AI) to enhance regulatory compliance across jurisdictions, focusing on automation, adaptability, and real-time responsiveness. It explores AI-driven frameworks—including Natural Language Processing (NLP), Machine Learning (ML), and Robotic Process Automation (RPA)—to optimize regulatory interpretation, anti-money laundering (AML) procedures, and Know Your Customer (KYC) requirements. The study further examines how AI models facilitate risk-b… | J34: C | K34: FinTech; nema UAV pojma u naslovu/sažetku | L34: C
A35: 31 | B35: 2021 | C35: Quantifying Waterfowl Numbers: Comparison of Drone and Ground-Based Survey Methods for Surveying Waterfowl on Artificial Waterbodies | D35: Drones | E35: Wildlife Ecology and Conservation | F35: https://openalex.org/W3119555133 | G35: https://doi.org/10.3390/drones5010005 | H35: drone, drones | I35: Drones are becoming a common method for surveying wildlife as they offer an aerial perspective of the landscape. For waterbirds in particular, drones can overcome challenges associated with surveying locations not accessible on foot. With the rapid uptake of drone technology for bird surveys, there is a need to compare and calibrate new technologies with existing survey methods. We compared waterfowl counts derived from ground- and drone-based survey methods. We sought to determine if group size and waterbody size influenced the difference between counts of non-nesting waterfowl and if detection of species varied between survey methods. Surveys of waterfowl were carried out at constructed ir… | J35: A | K35: Dron vs. terenski popis vodenih ptica | L35: A
A36: 32 | B36: 2025 | C36: Evaluating temporal trends in behavior and demographics to understand the lack of recovery of an endangered whale population | D36: Mspace (University of Manitoba) | E36: Marine animal studies overview | F36: https://openalex.org/W7137536149 | H36: drone | I36: Beluga whales (Delphinapterus leucas) are critical components of the Arctic marine ecosystem, and they face numerous threats from environmental changes and human activities. Understanding their population dynamics, habitat use, and social structure is crucial for their conservation. The research outlined here investigates the endangered Cumberland Sound beluga whale population using various techniques including drone surveys, aerial surveys, and satellite telemetry. The thesis begins with an overview of beluga whale ecology, behavior, and the threats they face, and explores how many of these aspects vary between populations. Satellite telemetry was used to explore behavioral trends, revealin… | J36: A | K36: Beluge, dronski popisi | L36: A
A37: 33 | B37: 2023 | C37: TLS2trees : A scalable tree segmentation pipeline for TLS data | D37: Methods in Ecology and Evolution | E37: Remote Sensing and LiDAR Applications | F37: https://openalex.org/W4387845585 | G37: https://doi.org/10.1111/2041-210x.14233 | H37: uav | I37: Abstract Above‐ground biomass (AGB) is an important metric used to quantify the mass of carbon stored in terrestrial ecosystems. For forests, this is routinely estimated at the plot scale (typically 1 ha) using inventory measurements and allometry. In recent years, terrestrial laser scanning (TLS) has appeared as a disruptive technology that can generate a more accurate assessment of tree and plot scale AGB; however, operationalising TLS methods has had to overcome a number of challenges. One such challenge is the segmentation of individual trees from plot level point clouds that are required to estimate woody volume, this is often done manually (e.g. with interactive point cloud editing sof… | J37: B | K37: TLS segmentacija stabala; UAV spomenut kao proširenje | L37: B
A38: 34 | B38: 2024 | C38: Old-growth mapping in Patagonia’s evergreen forests must integrate GEDI data to overcome NFI data limitations and to effectively support biodiversity conservation | D38: Forest Ecology and Management | E38: Remote Sensing and LiDAR Applications | F38: https://openalex.org/W4400416837 | G38: https://doi.org/10.1016/j.foreco.2024.122059 | H38: (nije u naslovu/sažetku) | I38: (sažetak nije dostupan — otvoriti poveznicu) | J38: B | K38: Kartiranje prašuma GEDI; sažetak nedostupan (provjeriti) | L38: B
A39: 35 | B39: 2024 | C39: Enhancing security and safety in quadcopter drones through unsupervised machine learning | D39: UVic’s Research and Learning Repository (University of Victoria) | E39: UAV Applications and Optimization | F39: https://openalex.org/W7199743103 | H39: drone, drones | I39: The increasing deployment of drones in various sectors has raised significant security concerns regarding their vulnerability to cyber-attacks and sensor data manipulation. Our project presents a comprehensive anomaly detection system designed to enhance drone security and safety through unsupervised machine learning. The implementation utilized a custom drone platform based on open-source components, enabling complete access to system internals and sensor data for security monitoring. Through systematic vulnerability analysis and testing, the project collected an extensive dataset comprising approximately 11.5 million network traffic samples and 1.25 million MAVLink messages, representing b… | J39: C | K39: Sigurnost kvadkoptera | L39: C
A40: 36 | B40: 2018 | C40: Elevate: Autonomous Pollution Surveillance System | D40: Automation and Autonomous Systems | E40: Air Quality Monitoring and Forecasting | F40: https://openalex.org/W2898544168 | H40: drone | I40: Epidemiological studies have shown that a close association is found between elevated air pollution levels and exacerbating cases of cardiovascular and respiratory diseases among older people and kids. Moreover, the presence of fine particulate in air makes it un-healthy to breathe which leads to lung cancer and cardiopulmonary mortality. Thus, in order to deploy effective air pollution control strategies, it is necessary to keep track of air quality levels throughout the day. The technology enabled solutions are required to collect and analyze air quality. In this research article, a novel hardware named “Elevate” has been proposed with aim to monitor air quality over a period of time. Basi… | J40: A | K40: Dron za nadzor onečišćenja zraka | L40: A
A41: 37 | B41: 2024 | C41: Monitoring and zoning soybean maturity using UAV remote sensing | D41: Industrial Crops and Products | E41: Remote Sensing in Agriculture | F41: https://openalex.org/W4402081459 | G41: https://doi.org/10.1016/j.indcrop.2024.119470 | H41: uav | I41: (sažetak nije dostupan — otvoriti poveznicu) | J41: B | K41: Zrelost soje | L41: B
A42: 38 | B42: 2025 | C42: Progress in the application of remote sensing for water quality and human health mapping in informal settlements of South Africa: A review | D42: Scientific African | E42: Water Quality and Pollution Assessment | F42: https://openalex.org/W4409994142 | G42: https://doi.org/10.1016/j.sciaf.2025.e02718 | H42: uavs, unmanned aerial | I42: Informal settlements in South Africa are a part of the urban landscape which is impossible to ignore due to their socio-economic contribution to the urban economies. However, the rapid expansion of these settlements exposes the population to various environmental hazards such as floods, pollution, and waterborne diseases and thus requires continuous monitoring. The use of remote sensing data has proved very effective for mapping water bodies, water quality, flood risk and water-borne diseases in parts of the world and in South Africa. This review highlights the extent to which remote sensing technology was used for mapping water quality in informal settlements, water-borne diseases, challeng… | J42: A | K42: Kakvoća vode u neformalnim naseljima; UAV preporučen | L42: A
A43: 39 | B43: 2025 | C43: Automated sugar beet seedling detection and mapping using a UAV-borne RGB camera and deep learning techniques | D43: Agroinženeriâ | E43: Remote Sensing in Agriculture | F43: https://openalex.org/W7117460984 | G43: https://doi.org/10.26897/2687-1149-2025-6-4-16 | H43: uav, uavs, unmanned aerial | I43: Accurate and timely assessment of plant stand density is crucial for modern crop production, directly impacting sugar beet yield and profitability. This study aims to develop and validate a highly accurate automated method for counting sugar beet seedlings using unmanned aerial vehicles (UAVs) and deep learning algorithms, optimizing both precision and processing speed. Field experiments were conducted in 2025 on commercial sugar beet fields in the Buzdyak district of the Republic of Bashkortostan. A DJI Phantom 4 Pro UAV equipped with an RGB camera captured aerial imagery from a 20-meter altitude. Initial vegetation segmentation employed the Excess Green (ExG) index, followed by binarizatio… | J43: B | K43: Šećerna repa, brojanje sadnica | L43: B
A44: 40 | B44: 2016 | C44: Urban stream deserts: Mapping a legacy of urbanization in the United States | D44: Applied Geography | E44: Land Use and Ecosystem Services | F44: https://openalex.org/W2222420283 | G44: https://doi.org/10.1016/j.apgeog.2015.12.008 | H44: (nije u naslovu/sažetku) | I44: (sažetak nije dostupan — otvoriti poveznicu) | J44: B | K44: Urbani potoci; sažetak nedostupan (provjeriti) | L44: B
A45: 41 | B45: 2024 | C45: UAV remote sensing phenotyping of wheat collection for response to water stress and yield prediction using machine learning | D45: Plant Stress | E45: Remote Sensing in Agriculture | F45: https://openalex.org/W4394960550 | G45: https://doi.org/10.1016/j.stress.2024.100464 | H45: uav | I45: Water stress is a significant challenge for global food production. Rainfall pattern is becoming unpredictable due to climate change that causes unprecedent water stress conditions in cereals production including wheat which is one of the important staple food crops. To sustain wheat production under water limiting conditions, there is an urgent need to develop drought-tolerant wheat varieties. For this, screening large numbers of wheat genotype for traits related to growth and yield under water stressed conditions is crucial. In this study, we deployed high-throughput phenotyping approaches, including uncrewed aerial vehicle (UAV)-based multispectral imaging, advanced machine and deep learn… | J45: B | K45: Fenotipizacija pšenice | L45: B
A46: 42 | B46: 2012 | C46: Computational Study on Micro-Pilot Flame Ignition Strategy for a Direct Injection Stratified Charge Rotary Engine | D46: CORE Scholar (Wright State University) | E46: Advanced Combustion Engine Technologies | F46: https://openalex.org/W2222754784 | H46: uav, unmanned aerial | I46: The Office of Security of Defense's Assured Fuels Initiative has recently been pressing for a single fuel battle space. This endeavor requires modifying many of the vehicle power plants currently in operation throughout the Armed Forces. The RQ-7 Shadow, an unmanned aerial vehicle (UAV) utilized by the Marine Corp and Army for reconnaissance purposes, is powered by UEL's AR741 rotary engine and functions on aviation fuel. One effort underway has been focused on developing this rotary engine system to operate on heavy fuels using direct injection technology and charge stratification. Although the rotary engine has many advantages over standard reciprocating engines, providing a reliable ignit… | J46: C | K46: Motor vojnog UAV-a | L46: C
A47: 43 | B47: 2025 | C47: An Overview of Unmanned Aerial Vehicles Technologies for Office Use and Services Delivery | D47: FUDMA Journal of Engineering and Technology | E47: UAV Applications and Optimization | F47: https://openalex.org/W7166539008 | G47: https://doi.org/10.33003/sx3s2787 | H47: drone, drones, unmanned aerial | I47: Universities are transforming into smart ecosystems driven (SED) by technology, transforming office logistics from inefficient processes to faster, more efficient, and innovative ones, thereby enhancing modern communication. Quadcopter drones (QCD) with delivery systems are revolutionizing office logistics by increasing efficiency, reducing costs, and boosting productivity. The paper explores the feasibility and functionality of a drone-based system for autonomously transporting small office items, aiming to improve efficiency, reduce human effort, and provide a reliable, secure intra-office delivery method. Unmanned Aerial Vehicles (drones) are transforming office spaces by eliminating huma… | J47: C | K47: Dostava u uredima | L47: C
A48: 44 | B48: 2023 | C48: The Role of Cold-Water Thermal Refuges for Stream Salmonids in a Changing Climate—Experiences from Atlantic Canada | D48: Fishes | E48: Fish Ecology and Management Studies | F48: https://openalex.org/W4386966520 | G48: https://doi.org/10.3390/fishes8090471 | H48: drone | I48: Thermal refuges are becoming increasingly influential for dictating the population status and spatial distribution of cold-water stenotherm salmonids in the mid- to southern extent of their range. The global climate is predicted to continue to warm, and therefore, the overall thermal suitability of freshwater habitats for stream salmonids is predicted to decline in concert. However, stream and river thermal heterogeneity will offer considerable resiliency for these populations. Thermal refuges are formed by many physical processes; common natural refuges include cold tributary plumes, groundwater springs, alcoves, and hyporheic upwellings. However, many anthropogenically formed refuges (such… | J48: A | K48: Termalni refugiji salmonida; dronske termalne kamere | L48: A
...

Sheet Uzorak_50_rano
A1: Uzorak B: 50 slučajnih zapisa, 2005.–2015. (seed 20260827)
A2: Žuti stupac = KONAČNA OCJENA (A/B/C), popunite ili potvrdite; prijedlog (AI) je samo pomoć.
A4: # | B4: Godina | C4: Naslov | D4: Časopis / izvor | E4: OpenAlex tema | F4: OpenAlex ID (poveznica) | G4: DOI | H4: UAV pojam | I4: Sažetak (skraćen) | J4: Prijedlog (AI) | K4: Obrazloženje prijedloga | L4: KONAČNA OCJENA | M4: Napomena ocjenjivača
A5: 1 | B5: 2006 | C5: Szendro - type Integrated Vegetation Fire Management--Wildfire Management Program from Hungary | E5: Fire effects on ecosystems | F5: https://openalex.org/W1902224079 | H5: uav | I5: Szendrő Fire Department is located in the northeastern part of Hungary. The main task is to fight against wildfire and mitigate the impact of fire at the Aggtelek National Park -- which belongs to the UNESCO World Heritage list. Because of greater effectiveness, in 2004 the Fire Department started a project named Integrated Vegetation Fire Management (IVFM). The IVFM consist of two main parts: Peripheries and Modules. The land use planning, finance, public relations, education, media connections, protective equipment belongs to Peripheries. The Modules are: Tower based environment monitoring and fire detection system, Mobile command control unit and Static and dynamic decision support system… | J5: A | K5: Upravljanje požarima, UAV izviđanje | L5: A
A6: 2 | B6: 2014 | C6: A Probabilistic Gas Patch Path Prediction Approach for Airborne Gas Source Localization in Non-Uniform Wind Fields | D6: Sensor Letters | E6: Insect Pheromone Research and Control | F6: https://openalex.org/W1986490556 | G6: https://doi.org/10.1166/sl.2014.3168 | H6: uav, unmanned aerial | I6: filter In this paper, we show that a micro unmanned aerial vehicle (UAV) equipped with commercially available gas sensors can address environmental monitoring and gas source localization (GSL) tasks. To account for the challenges of gas sensing under real-world conditions, we present a probabilistic approach for GSL that is based on a particle filter (PF). Simulation and real-world experiments demonstrate the suitability of this algorithm for micro UAV platforms. | J6: A | K6: Lokalizacija izvora plina mikro-UAV-om (okolišni monitoring) | L6: A
A7: 3 | B7: 2015 | C7: Approaching birds with drones: first experiments and ethical guidelines | D7: Biology Letters | E7: Wildlife-Road Interactions and Conservation | F7: https://openalex.org/W2111664716 | G7: https://doi.org/10.1098/rsbl.2014.0754 | H7: drone, drones, unmanned aerial | I7: Unmanned aerial vehicles, commonly called drones, are being increasingly used in ecological research, in particular to approach sensitive wildlife in inaccessible areas. Impact studies leading to recommendations for best practices are urgently needed. We tested the impact of drone colour, speed and flight angle on the behavioural responses of mallards Anas platyrhynchos in a semi-captive situation, and of wild flamingos (Phoenicopterus roseus) and common greenshanks (Tringa nebularia) in a wetland area. We performed 204 approach flights with a quadricopter drone, and during 80% of those we could approach unaffected birds to within 4 m. Approach speed, drone colour and repeated flights had no… | J7: A | K7: Prilaz pticama dronovima, etičke smjernice | L7: A
A8: 4 | B8: 2015 | C8: Ecological Benefits Evaluation in Ecological Migration Zone Based on Ecological Green Equivalent: A Case Study of Migration Zone in Yanchi County | D8: 亚洲农业研究：英文版 | E8: Land Use and Ecosystem Services | F8: https://openalex.org/W3142025330 | H8: uav | I8: With four ecological migration zones in Huamachi Town of Yanchi County in Ningxia Autonomous Region as the object of study,we carry out the evaluation of ecological benefits in ecological migration zone. Using the SPOT satellite remote sensing image in 2008 and UAV aerophotographic image in 2013,we first monitor and analyze the land use change over five years in the study area,and then adopt ecological green equivalent evaluation model for the evaluation of ecological benefits in the ecological migration zone. Studies have shown that:( i) from 2008 to 2013,the ecological green equivalent in the study area was increased and the ecological environment was improved;( ii) the ecological green eq… | J8: A | K8: Promjena uporabe zemljišta, UAV snimke | L8: A
A9: 5 | B9: 2007 | C9: Feature identification from commercial satellite images for military and homeland security operations in coastal zones | D9: Journal of Applied Remote Sensing | E9: Maritime and Coastal Archaeology | F9: https://openalex.org/W2121895676 | G9: https://doi.org/10.1117/1.2722339 | H9: unmanned aerial | I9: Supporting U.S. military operations and homeland security requirements in and around coastal zones, geospatial intelligence must be quickly integrated by tactical commanders to meet mission demands. Increasingly, unclassified commercial imagery and data acquired from conventional aircraft, unmanned aerial vehicles and satellites are being used by military and civilian analysts to populate coastal zone databases. This study assessed the suitability of commercially available satellite images for littoral warfare and homeland security operations. From the study, data that show the probabilities for extracting mandatory shoreline features from various images for maps produced at varying scale is… | J9: C | K9: Vojne/sigurnosne primjene snimaka | L9: C
A10: 6 | B10: 2013 | C10: Configuration and Specifications of an Unmanned Aerial Vehicle (UAV) for Early Site Specific Weed Management | D10: PLoS ONE | E10: Remote Sensing in Agriculture | F10: https://openalex.org/W2011270889 | G10: https://doi.org/10.1371/journal.pone.0058210 | H10: uav, unmanned aerial | I10: A new aerial platform has risen recently for image acquisition, the Unmanned Aerial Vehicle (UAV). This article describes the technical specifications and configuration of a UAV used to capture remote images for early season site- specific weed management (ESSWM). Image spatial and spectral properties required for weed seedling discrimination were also evaluated. Two different sensors, a still visible camera and a six-band multispectral camera, and three flight altitudes (30, 60 and 100 m) were tested over a naturally infested sunflower field. The main phases of the UAV workflow were the following: 1) mission planning, 2) UAV flight and image acquisition, and 3) image pre-processing. Three d… | J10: B | K10: Rano suzbijanje korova | L10: B
A11: 7 | B11: 2013 | C11: Estimating leaf carotenoid content in vineyards using high resolution hyperspectral imagery acquired from an unmanned aerial vehicle (UAV) | D11: Agricultural and Forest Meteorology | E11: Remote Sensing in Agriculture | F11: https://openalex.org/W2142087338 | G11: https://doi.org/10.1016/j.agrformet.2012.12.013 | H11: uav, unmanned aerial | I11: (sažetak nije dostupan — otvoriti poveznicu) | J11: B | K11: Karotenoidi u vinogradu | L11: B
A12: 8 | B12: 2015 | C12: Evaluation of an unmanned rotorcraft to monitor wintering waterbirds and coastal habitats in British Columbia, Canada | D12: Journal of Unmanned Vehicle Systems | E12: Wildlife-Road Interactions and Conservation | F12: https://openalex.org/W1892206252 | G12: https://doi.org/10.1139/juvs-2015-0019 | H12: uas, unmanned aircraft | I12: The effective protection of coastal and estuarine habitats requires reliable monitoring information on their use by waterbirds, and the use of small unmanned aircraft systems (UAS) may provide access to these habitats without disturbing birds. We evaluated the use of a rotary-wing UAS with a high-end consumer camera to identify and count wintering waterbirds at two coastal sites in British Columbia, Canada, in January 2015, and to map mudflat and marsh habitats. Photos of shorebirds, waterfowl, and seabird species were taken at varying altitudes, and disturbance of birds appeared minimal when the UAS was flown at heights ≥61 m. A ground resolution of ~1 cm/pixel was needed to discern plumage… | J12: A | K12: Vodene ptice i obalna staništa, mali UAS | L12: A
A13: 9 | B13: 2015 | C13: Deployment of an unmanned aerial system to assist in mapping an intermittent stream | D13: Hydrological Processes | E13: Flood Risk Assessment and Management | F13: https://openalex.org/W1692243462 | G13: https://doi.org/10.1002/hyp.10597 | H13: uas, unmanned aerial | I13: Abstract Recent growth in the capabilities of unmanned aerial vehicles and systems (UASs) as airborne platforms for collecting environmental data has been very rapid. There are now ample examples in the literature of UASs being deployed to map fine‐scale vegetation, glacial, soil and atmospheric conditions. The purported advantages of UASs are their ability to collect spatial data at lower cost, lower risk, higher resolution and higher frequency than ground surveys or satellite platforms. In this specific study, whether or not obtaining high‐resolution UAS imagery was advantageous for identifying an intermittent stream network was determined by comparing it with coarse‐scale satellite imager… | J13: A | K13: Kartiranje povremenog vodotoka UAS-om | L13: A
A14: 10 | B14: 2015 | C14: Wildlife research and management methods in the 21st century: Where do unmanned aircraft fit in? | D14: Journal of Unmanned Vehicle Systems | E14: Remote Sensing and LiDAR Applications | F14: https://openalex.org/W2130287418 | G14: https://doi.org/10.1139/juvs-2015-0021 | H14: uas, unmanned aircraft | I14: Since the turn of the century, emerging unmanned aircraft systems (UAS) have found increasingly diverse applications in wildlife science as convenient, very high-resolution remote sensing devices. Achieved or conceptualized applications include optical surveying and observation of animals, autonomous wildlife telemetry tracking, and habitat research and monitoring. As the technology continues to progress and interest from the wildlife science community grows, there may yet be much untapped potential for UAS to contribute to the discipline. We present a review of the published primary literature on the application of UAS in wildlife science and related fields. This is followed by a systematic… | J14: A | K14: Pregled: UAS u istraživanju divljači | L14: A
A15: 11 | B15: 2013 | C15: Method of Monitoring Cyanobacteria in Taihu Lake Based on the Low Altitude UAV with Visible-near Infrared Sensor | D15: Shandong Land and Resources | E15: Water Quality Monitoring Technologies | F15: https://openalex.org/W2354417035 | H15: uav | I15: Due to limitations of the access cycle,traditional means of satellite remote sensing is difficult to ensure the timeliness of data in time frequency. The low-altitude UnmannedAerialVehicle( UAV) equipped with a small light sensor,its maneuvers,rapid,economic and other advantages play an increasingly important role in the field of environmental monitoring. In order to meet monitoring requirements of cyanobacteria in TaihuLake,a visible-near infrared sensor monitoring method has been found based on the low-altitude UAV. On the basis of system planning and design platform,selecting Meiliang Lake area of Taihu lake to carry out the experiment. Based on previous experiences,using the Visible and … | J15: A | K15: Cijanobakterije u jezeru Taihu, UAV | L15: A
A16: 12 | B16: 2015 | C16: Using thermal infrared imagery produced by unmanned air vehicles to evaluate locations of ecological road structures | D16: Forestist | E16: Wildlife-Road Interactions and Conservation | F16: https://openalex.org/W2192551928 | G16: https://doi.org/10.17099/jffiu.76461 | H16: uav, uavs, unmanned aerial | I16: The aerial photos and satellite images are widely used and cost efficient data for monitoring and analysis of large areas in forestry activities. Nowadays, accurate and high resolution remote sensing data can be generated for large areas by using Unmanned Aerial Vehicles (UAV) integrated with sensors working in various spectral bands. Besides, the UAV systems (UAVs) have been used in interdisciplinary studies to produce data of large scale forested areas for desired time periods (i.e. in different seasons or different times of a day). In recent years, it has become more important to conduct studies on determination of wildlife corridors for controlling and planning of habitat fragmentation o… | J16: A | K16: Termalne UAV snimke za ekološke lokacije | L16: A
A17: 13 | B17: 2015 | C17: Comparison of atmospheric profile from ceilometer and UAV in the fog forest in central Taiwan. | D17: Japan Geoscience Union | E17: Remote Sensing and LiDAR Applications | F17: https://openalex.org/W2608167233 | H17: uav | I17: (sažetak nije dostupan — otvoriti poveznicu) | J17: A | K17: Atmosferski profil u maglenoj šumi, UAV | L17: A
A18: 14 | B18: 2009 | C18: INTEGRATION OF LOW COST GEOMATIC TECNIQUES TO SUPPORT THE ARCHITECTONICAL PROJECT. THE PERLO CASTLE AREA SURVEY | D18: PORTO Publications Open Repository TOrino (Politecnico di Torino) | E18: 3D Surveying and Cultural Heritage | F18: https://openalex.org/W92203316 | H18: uav, unmanned aerial | I18: In the high Tanaro Valley (Piedmont, Italy) the attestation of old pre-existence joined to the territory defence is possible to find numerous towers, castles, gouts and fortress. Today the most part of these cultural heritage are in ruin. Close to the municipality of Perlo few meters from the principal street, following a winding path is possible to arrive to a little hill; there the ruins of the old Castle of Perlo are hide from a rigorous vegetation. The old might of the fortress is lost today, is like an explosion of stone fragments swallow from the natural environment. The walls cut in some cases the hillok and the old towers are like rock spur. The requirement of the municipal administr… | J18: C | K18: Arhitektonski projekt, geomatika | L18: C
A19: 15 | B19: 2007 | C19: Biology of Apis dorsata in Vietnam | D19: Springer Link (Chiba Institute of Technology) | E19: Insect and Pesticide Research | F19: https://openalex.org/W4387391007 | G19: https://doi.org/10.1051/apido:2007002/pdf | H19: drone, drones | I19: This paper studies the biology of A. dorsata in the Melaleuca forest of Vietnam. The width of 158 A. dorsata combs was from 43–162 cm, and the height from 23–90 cm. About 3–4 weeks after nesting, a colony could store 4.1 $\pm$ 2.6 kg of honey. The thickness of the worker brood comb was 3.3 cm and of the drone was 3.7 cm, but that of the honey comb was possibly 19.0 cm. The width of 10 continuous drone cells (58.1 $\pm$ 1.4 cm, n = 90) is significantly larger than that of worker cells (55.7 $\pm$ 1.7, n = 330). The depth of drone cells was 19.0 $\pm$ 0.4 mm (n = 90) and of worker cells was 17.4 $\pm$ 1.5 mm (n = 225). The weights of the newly emerged worker, drone and queen bees were 159.9 $\… | J19: C | K19: „Drone“ = trut (Apis dorsata) | L19: C
A20: 16 | B20: 2015 | C20: Close Range Photogrammetry in the Survey of the Coastal Area Geoecological Conditions (on the Example of Portugal) | D20: Earth Sciences | E20: Coastal and Marine Dynamics | F20: https://openalex.org/W2196131291 | G20: https://doi.org/10.11648/j.earth.s.2015040501.17 | H20: drone, uav, unmanned aerial | I20: Close range digital photogrammetry, which involves the application of unmanned aerial vehicle (UAV), has been used in a growing number of diverse applications across different scientific disciplines. Our objective was to use the mentioned method in the survey of the contemporary geoecological conditions of the coastal area on the example of Portuguese northwest coastal zone. The coastal zone can be subdivided into two geomorphological sectors: Sector 1, between the Minho River and the town of Espinho, where the coastal segments consist of estuaries, sandy and shingle beaches with rocky outcrops, and Holocene dune systems. The estuaries and the foredunes in particular are very degraded by hum… | J20: A | K20: Geoekološki uvjeti obale, UAV fotogrametrija | L20: A
